Workbook

Sheet Summary
A1: Trade Journal · Week 44 · 2026
A2: Generated (Berlin) | B2: 46323.724 | C2: Period | D2: Mon 26 Oct 2026 to Sun 01 Nov 2026 (New York dates)
A3: Generated (New York) | B3: 46323.515
A4: Account | B4: Paper (practice money)
A5: Auto-trader switch | B5: ON
A7: Measure | B7: Value
A8: Orders placed | B8: =COUNTIF(Orders!$E$2:$E$42,"BUY")+COUNTIF(Orders!$E$2:$E$42,"SELL")
A9: Buy orders | B9: =COUNTIF(Orders!$E$2:$E$42,"BUY")
A10: Sell orders | B10: =COUNTIF(Orders!$E$2:$E$42,"SELL")
A11: Filled orders | B11: =COUNTIF(Orders!$I$2:$I$42,"filled")
A12: Total bought $ | B12: =SUMIFS(Orders!$L$2:$L$42,Orders!$E$2:$E$42,"BUY")
A13: Total sold $ | B13: =SUMIFS(Orders!$L$2:$L$42,Orders!$E$2:$E$42,"SELL")
A14: Closed round trips | B14: =COUNTIF('Round trips'!$P$2:$P$39,"Closed")
A15: Open lots | B15: =COUNTIF('Round trips'!$P$2:$P$39,"Open")
A16: Realized P/L $ | B16: =SUM('Round trips'!$L$2:$L$39)
A17: Winning round trips | B17: =COUNTIFS('Round trips'!$P$2:$P$39,"Closed",'Round trips'!$L$2:$L$39,">0")
A18: Win rate | B18: =IFERROR(B17/B14,0)
A20: Times: New York is the exchange clock; Berlin is your local time. Round trips match buys to sells first-in-first-out.
A21: Source: Alpaca order data recorded by the auto-trader at the moment each order was placed.

Sheet Orders
A1: No | B1: Time Berlin | C1: Time New York | D1: Time UTC | E1: Side | F1: Symbol | G1: Company | H1: Exchange | I1: Status | J1: Qty filled | K1: Avg fill price $ | L1: Fill value $ | M1: Requested $ | N1: Requested qty | O1: Rule | P1: Reason | Q1: Greens (of 5) | R1: Time machine | S1: TM hit rate | T1: TM green days | U1: TM avg 5-day % | V1: Master switch 6-mo return % | W1: Agent rank | X1: 1 Data real | Y1: Source spread % | Z1: 2 Organic | AA1: Organic score | AB1: Organic flags | AC1: 3 Prediction | AD1: Call | AE1: Target $ | AF1: Range low $ | AG1: Range high $ | AH1: Call due | AI1: Confidence | AJ1: 4 News | AK1: Headlines (72h) | AL1: Top headline | AM1: Price at decision $ | AN1: Move today % | AO1: Account equity before $ | AP1: Cash before $ | AQ1: Slot % | AR1: Position qty before | AS1: Avg entry before $ | AT1: P/L % before | AU1: Account | AV1: Order ID | AW1: Client order ID | AX1: Decided at (UTC) | AY1: Filled at (UTC) | AZ1: Agent run (UTC) | BA1: Error
A2: 1 | B2: 46322.716 | C2: 46322.508 | D2: 46322.675 | E2: BUY | F2: TMO | G2: Thermo Fisher Scientific, Inc. | H2: NYSE | I2: filled | J2: 11.986804 | K2: 694.93 | L2: =IF(AND(ISNUMBER(J2),ISNUMBER(K2)),J2*K2,"") | M2: 8330 | O2: 4+/5 green | P2: 5 of 5 green, time machine green, rank #1, 8.33% of the $100,000.00 account | Q2: 5 | R2: ok | S2: 0.667 | T2: 81 | U2: 0.0135 | V2: -0.0173 | W2: 1 | X2: ok | Y2: 0.0006 | Z2: ok | AA2: 100 | AC2: ok | AD2: up | AE2: 704.5304 | AF2: 679.4169 | AG2: 729.644 | AH2: 46329 | AI2: 0.54 | AJ2: ok | AK2: 1 | AL2: Thermo Fisher Scientific Experts to Host Webinar on Clario Endpoint Data Solutions | AM2: 694.485 | AN2: 0.0141 | AO2: 100000 | AP2: 100000 | AQ2: 0.0833 | AU2: paper | AV2: a17cede0-0466-4ec2-b2e1-ee5ddd1134cf | AW2: tdagent-buy-TMO-1793117490105 | AX2: 46322.675 | AY2: 46322.675 | AZ2: 46322.674
A3: 2 | B3: 46322.796 | C3: 46322.587 | D3: 46322.754 | E3: BUY | F3: SHEL | G3: Shell plc American Depositary Shares (Each represents two Ordinary shares) | H3: NYSE | I3: filled | J3: 79.416754 | K3: 104.93 | L3: =IF(AND(ISNUMBER(J3),ISNUMBER(K3)),J3*K3,"") | M3: 8333.21 | O3: 4+/5 green | P3: 5 of 5 green, time machine green, rank #1, 8.33% of the $100,038.60 account | Q3: 5 | R3: ok | S3: 0.652 | T3: 92 | U3: 0.0121 | V3: -0.0173 | W3: 1 | X3: ok | Y3: 0 | Z3: ok | AA3: 100 | AC3: ok | AD3: up | AE3: 106.142 | AF3: 103.062 | AG3: 109.222 | AH3: 46329 | AI3: 0.58 | AJ3: ok | AK3: 3 | AL3: Shell plc Announces Share Buyback Transaction | AM3: 104.91 | AN3: -0.0187 | AO3: 100038.6 | AP3: 91670.01 | AQ3: 0.0833 | AU3: paper | AV3: 12db7300-b65a-4371-a182-4bcc07ceda77 | AW3: tdagent-buy-SHEL-1793124338749 | AX3: 46322.754 | AY3: 46322.754 | AZ3: 46322.754
A4: 3 | B4: 46322.868 | C4: 46322.659 | D4: 46322.826 | E4: SELL | F4: SHEL | G4: SHEL | H4: NYSE | I4: filled | J4: 79.416754 | K4: 104.96 | L4: =IF(AND(ISNUMBER(J4),ISNUMBER(K4)),J4*K4,"") | N4: 79.416754 | O4: evening under 5% | P4: Evening: +0.0% from the buy price (under +5%), sold 10 min before the close | Q4: 5 | R4: ok | S4: 0.652 | T4: 92 | U4: 0.0121 | V4: -0.1111 | X4: ok | Y4: 0.0001 | Z4: ok | AA4: 100 | AC4: ok | AD4: up | AE4: 106.1815 | AF4: 103.1027 | AG4: 109.2604 | AH4: 46329 | AI4: 0.58 | AJ4: ok | AK4: 5 | AL4: 'Washington discusses Russian deals for US oil majors in Ukraine peace talks' - Financial Times | AM4: 104.94 | AN4: -0.0183 | AO4: 100056.57 | AP4: 83336.81 | AQ4: 0.0833 | AR4: 79.416754 | AS4: 104.93 | AT4: 0.0003 | AU4: paper | AV4: be781221-5b78-4809-97c9-dde0425348d5 | AW4: tdagent-sell-SHEL-1793130578234 | AX4: 46322.826 | AY4: 46322.826 | AZ4: 46322.825
A5: 4 | B5: 46322.868 | C5: 46322.66 | D5: 46322.826 | E5: SELL | F5: TMO | G5: TMO | H5: NYSE | I5: filled | J5: 11.986804 | K5: 699.16667 | L5: =IF(AND(ISNUMBER(J5),ISNUMBER(K5)),J5*K5,"") | N5: 11.986804 | O5: evening under 5% | P5: Evening: +0.6% from the buy price (under +5%), sold 10 min before the close | Q5: 5 | R5: ok | S5: 0.667 | T5: 81 | U5: 0.0135 | V5: -0.1111 | X5: ok | Y5: 0.0007 | Z5: ok | AA5: 100 | AC5: ok | AD5: up | AE5: 710.0776 | AF5: 684.5837 | AG5: 735.5715 | AH5: 46329 | AI5: 0.54 | AJ5: ok | AK5: 1 | AL5: Thermo Fisher Scientific Experts to Host Webinar on Clario Endpoint Data Solutions | AM5: 699.8 | AN5: 0.022 | AO5: 100056.57 | AP5: 83336.81 | AQ5: 0.0833 | AR5: 11.986804 | AS5: 694.93 | AT5: 0.0065 | AU5: paper | AV5: 3df9c111-1586-40fd-a37a-ab0a53ccf9d7 | AW5: tdagent-sell-TMO-1793130578875 | AX5: 46322.826 | AY5: 46322.826 | AZ5: 46322.825
A6: 5 | B6: 46323.607 | C6: 46323.398 | D6: 46323.565 | E6: BUY | F6: TMO | G6: Thermo Fisher Scientific, Inc. | H6: NYSE | I6: filled | J6: 11.937064 | K6: 698.19344 | L6: =IF(AND(ISNUMBER(J6),ISNUMBER(K6)),J6*K6,"") | M6: 8334.39 | O6: 4+/5 green | P6: 5 of 5 green, time machine green, rank #1, 8.33% of the $100,052.80 account | Q6: 5 | R6: ok | S6: 0.667 | T6: 81 | U6: 0.0134 | V6: -0.1111 | W6: 1 | X6: ok | Y6: 0.001 | Z6: ok | AA6: 100 | AC6: ok | AD6: up | AE6: 703.0821 | AF6: 678.0519 | AG6: 728.1123 | AH6: 46330 | AI6: 0.54 | AJ6: ok | AK6: 1 | AL6: Thermo Fisher Scientific Experts to Host Webinar on Clario Endpoint Data Solutions | AM6: 692.41 | AN6: 0.012 | AO6: 100052.8 | AP6: 100052.8 | AQ6: 0.0833 | AU6: paper | AV6: 75ff6654-caa0-43af-a8e3-46fa207bc64a | AW6: tdagent-buy-TMO-1793194262152 | AX6: 46323.563 | AY6: 46323.565 | AZ6: 46323.563
A7: 6 | B7: 46323.607 | C7: 46323.398 | D7: 46323.565 | E7: BUY | F7: DT | G7: Dynatrace, Inc. | H7: NYSE | I7: filled | J7: 130.29531 | K7: 63.965309 | L7: =IF(AND(ISNUMBER(J7),ISNUMBER(K7)),J7*K7,"") | M7: 8334.39 | O7: 4+/5 green | P7: 5 of 5 green, time machine green, rank #2, 8.33% of the $100,052.80 account | Q7: 5 | R7: ok | S7: 0.647 | T7: 51 | U7: 0.0133 | V7: -0.1111 | W7: 2 | X7: ok | Y7: 0.0058 | Z7: ok | AA7: 100 | AC7: ok | AD7: up | AE7: 65.2238 | AF7: 61.5643 | AG7: 68.8832 | AH7: 46330 | AI7: 0.55 | AJ7: ok | AK7: 3 | AL7: Analyst Raises Price Target for Dynatrace | AM7: 63.39 | AN7: -0.0065 | AO7: 100052.8 | AP7: 100052.8 | AQ7: 0.0833 | AU7: paper | AV7: ea46df9e-798f-47b6-8f79-15985b1f21c1 | AW7: tdagent-buy-DT-1793194262796 | AX7: 46323.563 | AY7: 46323.565 | AZ7: 46323.563
A8: 7 | B8: 46323.607 | C8: 46323.399 | D8: 46323.566 | E8: BUY | F8: MNST | G8: Monster Beverage Corporation | H8: NASDAQ | I8: filled | J8: 184.54039 | K8: 45.162906 | L8: =IF(AND(ISNUMBER(J8),ISNUMBER(K8)),J8*K8,"") | M8: 8334.39 | O8: 4+/5 green | P8: 5 of 5 green, time machine green, rank #3, 8.33% of the $100,052.80 account | Q8: 5 | R8: ok | S8: 0.652 | T8: 89 | U8: 0.0089 | V8: -0.1111 | W8: 3 | X8: ok | Y8: 0.0071 | Z8: ok | AA8: 100 | AC8: ok | AD8: up | AE8: 46.063 | AF8: 44.4805 | AG8: 47.6454 | AH8: 46330 | AI8: 0.53 | AJ8: ok | AK8: 4 | AL8: JP Morgan Maintains Neutral on Monster Beverage, Lowers Price Target to $49 | AM8: 45.11 | AN8: -0.0219 | AO8: 100052.8 | AP8: 100052.8 | AQ8: 0.0833 | AU8: paper | AV8: 1618d695-4afd-42f8-b0f6-9dbbedd13f56 | AW8: tdagent-buy-MNST-1793194263216 | AX8: 46323.563 | AY8: 46323.566 | AZ8: 46323.563
A9: 8 | B9: 46323.607 | C9: 46323.399 | D9: 46323.565 | E9: BUY | F9: CBOE | G9: Cboe Global Markets, Inc. | H9: BATS | I9: filled | J9: 25.834718 | K9: 322.60387 | L9: =IF(AND(ISNUMBER(J9),ISNUMBER(K9)),J9*K9,"") | M9: 8334.39 | O9: 4+/5 green | P9: 5 of 5 green, time machine green, rank #4, 8.33% of the $100,052.80 account | Q9: 5 | R9: ok | S9: 0.582 | T9: 67 | U9: 0.0026 | V9: -0.1111 | W9: 4 | X9: ok | Y9: 0 | Z9: ok | AA9: 100 | AC9: ok | AD9: up | AE9: 331.8585 | AF9: 314.9122 | AG9: 348.8048 | AH9: 46330 | AI9: 0.57 | AJ9: ok | AK9: 3 | AL9: JPMorgan Adjusts Price Target on Cboe Global Markets to $332 From $288 | AM9: 325.08 | AN9: -0.0295 | AO9: 100052.8 | AP9: 100052.8 | AQ9: 0.0833 | AU9: paper | AV9: 9bdcd091-8a94-4f6c-90f4-0dd5ee0bbaf3 | AW9: tdagent-buy-CBOE-1793194263728 | AX9: 46323.563 | AY9: 46323.565 | AZ9: 46323.563
A10: 9 | B10: 46323.607 | C10: 46323.398 | D10: 46323.565 | E10: BUY | F10: MCK | G10: McKesson Corporation | H10: NYSE | I10: filled | J10: 8.6201353 | K10: 966.85025 | L10: =IF(AND(ISNUMBER(J10),ISNUMBER(K10)),J10*K10,"") | M10: 8334.39 | O10: 4+/5 green | P10: 5 of 5 green, time machine green, rank #5, 8.33% of the $100,052.80 account | Q10: 5 | R10: ok | S10: 0.588 | T10: 68 | U10: 0.0019 | V10: -0.1111 | W10: 5 | X10: ok | Y10: 0 | Z10: ok | AA10: 100 | AC10: ok | AD10: up | AE10: 982.3085 | AF10: 943.6373 | AG10: 1020.9796 | AH10: 46330 | AI10: 0.56 | AJ10: ok | AK10: 2 | AL10: Here's How Much $100 Invested In McKesson 5 Years Ago Would Be Worth Today | AM10: 966.84 | AN10: -0.0255 | AO10: 100052.8 | AP10: 100052.8 | AQ10: 0.0833 | AU10: paper | AV10: 6189b904-77fc-4fcf-b41f-bde0ff4f39db | AW10: tdagent-buy-MCK-1793194264162 | AX10: 46323.563 | AY10: 46323.565 | AZ10: 46323.563
A11: 10 | B11: 46323.606 | C11: 46323.398 | D11: 46323.564 | E11: BUY | F11: SHEL | G11: Shell plc American Depositary Shares (Each represents two Ordinary shares) | H11: NYSE | I11: filled | J11: 79.375048 | K11: 105 | L11: =IF(AND(ISNUMBER(J11),ISNUMBER(K11)),J11*K11,"") | M11: 8334.39 | O11: 4+/5 green | P11: 4 of 5 green, time machine green, rank #6, 8.33% of the $100,052.80 account | Q11: 4 | R11: ok | S11: 0.659 | T11: 91 | U11: 0.0124 | V11: -0.1111 | W11: 6 | X11: ok | Y11: 0.0025 | Z11: ok | AA11: 100 | AC11: ok | AD11: up | AE11: 106.0087 | AF11: 102.9244 | AG11: 109.093 | AH11: 46330 | AI11: 0.58 | AJ11: watch | AK11: 8 | AL11: 'Washington discusses Russian deals for US oil majors in Ukraine peace talks' - Financial Times | AM11: 105.04 | AN11: -0.02 | AO11: 100052.8 | AP11: 100052.8 | AQ11: 0.0833 | AU11: paper | AV11: f2c34f6c-bb0c-4e2b-a829-02bd8a0f636f | AW11: tdagent-buy-SHEL-1793194264666 | AX11: 46323.563 | AY11: 46323.564 | AZ11: 46323.563
A12: 11 | B12: 46323.606 | C12: 46323.398 | D12: 46323.565 | E12: BUY | F12: ILMN | G12: Illumina, Inc. Common Stock | H12: NASDAQ | I12: filled | J12: 29.659715 | K12: 281 | L12: =IF(AND(ISNUMBER(J12),ISNUMBER(K12)),J12*K12,"") | M12: 8334.39 | O12: 4+/5 green | P12: 5 of 5 green, time machine green, rank #9, 8.33% of the $100,052.80 account | Q12: 5 | R12: ok | S12: 0.592 | T12: 125 | U12: 0.0155 | V12: -0.1111 | W12: 9 | X12: ok | Y12: 0.0029 | Z12: ok | AA12: 100 | AC12: ok | AD12: up | AE12: 287.5899 | AF12: 267.1151 | AG12: 308.0647 | AH12: 46330 | AI12: 0.53 | AJ12: ok | AK12: 0 | AM12: 278.6 | AN12: 0.0312 | AO12: 100052.8 | AP12: 100052.8 | AQ12: 0.0833 | AU12: paper | AV12: 980f13dc-f907-4bd4-b53e-7799785ee61b | AW12: tdagent-buy-ILMN-1793194266066 | AX12: 46323.563 | AY12: 46323.565 | AZ12: 46323.563
A13: 12 | B13: 46323.606 | C13: 46323.398 | D13: 46323.565 | E13: BUY | F13: UTHR | G13: United Therapeutics Corporation Common Stock | H13: NASDAQ | I13: filled | J13: 14.223462 | K13: 585.96 | L13: =IF(AND(ISNUMBER(J13),ISNUMBER(K13)),J13*K13,"") | M13: 8334.39 | O13: 4+/5 green | P13: 5 of 5 green, time machine green, rank #10, 8.33% of the $100,052.80 account | Q13: 5 | R13: ok | S13: 0.569 | T13: 51 | U13: 0.0118 | V13: -0.1111 | W13: 10 | X13: ok | Y13: 0 | Z13: ok | AA13: 100 | AC13: ok | AD13: up | AE13: 604.2865 | AF13: 571.9452 | AG13: 636.6278 | AH13: 46330 | AI13: 0.55 | AJ13: ok | AK13: 0 | AM13: 591.35 | AN13: -0.0023 | AO13: 100052.8 | AP13: 100052.8 | AQ13: 0.0833 | AU13: paper | AV13: 4bf78c8b-c039-475a-999c-1bf4c352180c | AW13: tdagent-buy-UTHR-1793194266530 | AX13: 46323.563 | AY13: 46323.565 | AZ13: 46323.563
A14: 13 | B14: 46323.606 | C14: 46323.398 | D14: 46323.565 | E14: BUY | F14: EBAY | G14: eBay Inc. Common Stock | H14: NASDAQ | I14: filled | J14: 70.132683 | K14: 118.83732 | L14: =IF(AND(ISNUMBER(J14),ISNUMBER(K14)),J14*K14,"") | M14: 8334.39 | O14: 4+/5 green | P14: 5 of 5 green, time machine green, rank #11, 8.33% of the $100,052.80 account | Q14: 5 | R14: ok | S14: 0.55 | T14: 40 | U14: 0.0055 | V14: -0.1111 | W14: 11 | X14: ok | Y14: 0.0044 | Z14: ok | AA14: 100 | AC14: ok | AD14: up | AE14: 119.7698 | AF14: 114.8704 | AG14: 124.6691 | AH14: 46330 | AI14: 0.55 | AJ14: ok | AK14: 5 | AL14: UBS Maintains Neutral on eBay, Raises Price Target to $131 | AM14: 118.33 | AN14: -0.0067 | AO14: 100052.8 | AP14: 100052.8 | AQ14: 0.0833 | AU14: paper | AV14: 8449c305-1c64-40c9-a24f-a14b858d4888 | AW14: tdagent-buy-EBAY-1793194267013 | AX14: 46323.563 | AY14: 46323.565 | AZ14: 46323.563
A15: 14 | B15: 46323.607 | C15: 46323.399 | D15: 46323.566 | E15: BUY | F15: OXY | G15: Occidental Petroleum Corporation | H15: NYSE | I15: filled | J15: 132.2952 | K15: 62.998354 | L15: =IF(AND(ISNUMBER(J15),ISNUMBER(K15)),J15*K15,"") | M15: 8334.39 | O15: 4+/5 green | P15: 4 of 5 green, time machine green, rank #12, 8.33% of the $100,052.80 account | Q15: 4 | R15: ok | S15: 0.621 | T15: 58 | U15: 0.0105 | V15: -0.1111 | W15: 12 | X15: ok | Y15: 0.0065 | Z15: ok | AA15: 100 | AC15: ok | AD15: up | AE15: 63.7925 | AF15: 61.1362 | AG15: 66.4489 | AH15: 46330 | AI15: 0.54 | AJ15: watch | AK15: 7 | AL15: Goldman Sachs Downgrades Occidental Petroleum to Neutral | AM15: 63.14 | AN15: -0.0209 | AO15: 100052.8 | AP15: 100052.8 | AQ15: 0.0833 | AU15: paper | AV15: e2f8f479-97ed-463a-aab1-2ca11da16008 | AW15: tdagent-buy-OXY-1793194267523 | AX15: 46323.563 | AY15: 46323.566 | AZ15: 46323.563
A16: 15 | B16: 46323.607 | C16: 46323.399 | D16: 46323.566 | E16: BUY | F16: IQV | G16: IQVIA Holdings Inc. | H16: NYSE | I16: filled | J16: 30.35976 | K16: 274.52062 | L16: =IF(AND(ISNUMBER(J16),ISNUMBER(K16)),J16*K16,"") | M16: 8334.39 | O16: 4+/5 green | P16: 4 of 5 green, time machine green, rank #13, 8.33% of the $100,052.80 account | Q16: 4 | R16: ok | S16: 0.6 | T16: 75 | U16: 0.0142 | V16: -0.1111 | W16: 13 | X16: ok | Y16: 0.0047 | Z16: ok | AA16: 100 | AC16: ok | AD16: up | AE16: 275.4603 | AF16: 265.4096 | AG16: 285.511 | AH16: 46330 | AI16: 0.53 | AJ16: watch | AK16: 7 | AL16: IQVIA Hldgs Q3 2026 Earnings Call Transcript | AM16: 270.175 | AN16: -0.0092 | AO16: 100052.8 | AP16: 100052.8 | AQ16: 0.0833 | AU16: paper | AV16: dcb95512-fd40-4530-b67d-8e5ef4305ac4 | AW16: tdagent-buy-IQV-1793194268057 | AX16: 46323.563 | AY16: 46323.566 | AZ16: 46323.563
A17: 16 | B17: 46323.607 | C17: 46323.399 | D17: 46323.566 | E17: BUY | F17: PBR.A | G17: Petroleo Brasileiro S.A.-Petrobras | H17: NYSE | I17: filled | J17: 423.15907 | K17: 19.69562 | L17: =IF(AND(ISNUMBER(J17),ISNUMBER(K17)),J17*K17,"") | M17: 8334.39 | O17: 4+/5 green | P17: 4 of 5 green, time machine green, rank #14, 8.33% of the $100,052.80 account | Q17: 4 | R17: ok | S17: 0.652 | T17: 66 | U17: 0.0247 | V17: -0.1111 | W17: 14 | X17: ok | Y17: 0.0018 | Z17: watch | AA17: 70 | AB17: One day (-15.4%) did 121% of the 10-day move. The trend rests on a single jump.; Price gapped 16.8% at an open in the last week. | AC17: ok | AD17: up | AE17: 20.3103 | AF17: 18.9221 | AG17: 21.6984 | AH17: 46330 | AI17: 0.53 | AJ17: ok | AK17: 3 | AL17: Halliburton Deploys ROCS Technology With Petrobras in Brazil | AM17: 19.72 | AN17: -0.0075 | AO17: 100052.8 | AP17: 100052.8 | AQ17: 0.0833 | AU17: paper | AV17: d24a5b49-4f8b-4052-bbd2-144f6d025701 | AW17: tdagent-buy-PBR.A-1793194268661 | AX17: 46323.563 | AY17: 46323.566 | AZ17: 46323.563
A18: 17 | B18: 46323.609 | C18: 46323.401 | D18: 46323.567 | E18: SELL | F18: IQV | G18: IQV | H18: NYSE | I18: filled | J18: 15.17988 | K18: 273.44 | L18: =IF(AND(ISNUMBER(J18),ISNUMBER(K18)),J18*K18,"") | N18: 15.17988 | O18: 3 green: sell half | P18: 3 of 5 green: start selling (half) | Q18: 3 | R18: ok | S18: 0.6 | T18: 75 | U18: 0.0142 | V18: -0.1111 | X18: watch | Y18: 0.0091 | Z18: ok | AA18: 100 | AC18: ok | AD18: up | AE18: 275.8908 | AF18: 266.0138 | AG18: 285.7679 | AH18: 46330 | AI18: 0.53 | AJ18: watch | AK18: 7 | AL18: IQVIA Hldgs Q3 2026 Earnings Call Transcript | AM18: 271.94 | AN18: 0.0018 | AO18: 99990.35 | AP18: 40.24 | AQ18: 0.0833 | AR18: 30.35976 | AS18: 274.52062 | AT18: -0.0028 | AU18: paper | AV18: 23c6235d-dfef-4aeb-a7b4-d002f9b5f79f | AW18: tdagent-sell-IQV-1793194607983 | AX18: 46323.567 | AY18: 46323.567 | AZ18: 46323.567
A19: 18 | B19: 46323.609 | C19: 46323.401 | D19: 46323.567 | E19: SELL | F19: PBR.A | G19: PBR.A | H19: NYSE | I19: filled | J19: 211.57953 | K19: 19.755625 | L19: =IF(AND(ISNUMBER(J19),ISNUMBER(K19)),J19*K19,"") | N19: 211.57953 | O19: 3 green: sell half | P19: 3 of 5 green: start selling (half) | Q19: 3 | R19: ok | S19: 0.652 | T19: 66 | U19: 0.0247 | V19: -0.1111 | X19: ok | Y19: 0.0005 | Z19: watch | AA19: 70 | AB19: One day (-15.4%) did 107% of the 10-day move. The trend rests on a single jump.; Price gapped 16.8% at an open in the last week. | AC19: watch | AD19: flat | AE19: 19.76 | AF19: 18.3771 | AG19: 21.1429 | AH19: 46330 | AI19: 0.5 | AJ19: ok | AK19: 3 | AL19: Halliburton Deploys ROCS Technology With Petrobras in Brazil | AM19: 19.75 | AN19: 0.0003 | AO19: 99990.35 | AP19: 40.24 | AQ19: 0.0833 | AR19: 423.15907 | AS19: 19.69562 | AT19: 0.0028 | AU19: paper | AV19: e3451ca4-e963-4073-ad76-f95ca1253ccb | AW19: tdagent-sell-PBR.A-1793194608171 | AX19: 46323.567 | AY19: 46323.567 | AZ19: 46323.567
A20: 19 | B20: 46323.661 | C20: 46323.453 | D20: 46323.62 | E20: SELL | F20: UTHR | G20: UTHR | H20: NASDAQ | I20: filled | J20: 7.1117312 | K20: 588.24 | L20: =IF(AND(ISNUMBER(J20),ISNUMBER(K20)),J20*K20,"") | N20: 7.1117312 | O20: 3 green: sell half | P20: 3 of 5 green: start selling (half) | Q20: 3 | R20: ok | S20: 0.569 | T20: 51 | U20: 0.0118 | V20: -0.1111 | X20: watch | Y20: 0.0079 | Z20: ok | AA20: 100 | AC20: watch | AD20: flat | AE20: 589.155 | AF20: 556.9173 | AG20: 621.3927 | AH20: 46330 | AI20: 0.5 | AJ20: ok | AK20: 1 | AL20: $100 Invested In United Therapeutics 15 Years Ago Would Be Worth This Much Today | AM20: 589.155 | AN20: -0.0037 | AO20: 100467.14 | AP20: 8370.92 | AQ20: 0.0833 | AR20: 14.223462 | AS20: 585.96 | AT20: 0.0047 | AU20: paper | AV20: 7bad1f9c-33ad-4b49-9f35-6a76bd48b748 | AW20: tdagent-sell-UTHR-1793199151204 | AX20: 46323.62 | AY20: 46323.62 | AZ20: 46323.62
A21: 20 | B21: 46323.672 | C21: 46323.464 | D21: 46323.63 | E21: BUY | F21: ADI | G21: Analog Devices, Inc. Common Stock | H21: NASDAQ | I21: filled | J21: 2.4606118 | K21: 425 | L21: =IF(AND(ISNUMBER(J21),ISNUMBER(K21)),J21*K21,"") | M21: 1045.77 | O21: 4+/5 green | P21: 5 of 5 green, time machine green, rank #1, 8.33% of the $12,554.32 free cash split 12 ways | Q21: 5 | R21: ok | S21: 0.707 | T21: 75 | U21: 0.0147 | V21: -0.1395 | W21: 1 | X21: ok | Y21: 0 | Z21: ok | AA21: 100 | AC21: ok | AD21: up | AE21: 431.932 | AF21: 413.102 | AG21: 450.762 | AH21: 46330 | AI21: 0.53 | AJ21: ok | AK21: 0 | AM21: 424.4 | AN21: -0.002 | AO21: 100357.58 | AP21: 12554.32 | AQ21: 0.0833 | AU21: paper | AV21: e231ad14-a73b-476f-af0e-82110bbe24ec | AW21: tdagent-buy-ADI-1793200046969 | AX21: 46323.63 | AY21: 46323.63 | AZ21: 46323.63
A22: 21 | B22: 46323.672 | C22: 46323.464 | D22: 46323.63 | E22: BUY | F22: NTRA | G22: Natera, Inc. Common Stock | H22: NASDAQ | I22: filled | J22: 2.4344911 | K22: 429.56 | L22: =IF(AND(ISNUMBER(J22),ISNUMBER(K22)),J22*K22,"") | M22: 1045.77 | O22: 4+/5 green | P22: 5 of 5 green, time machine green, rank #2, 8.33% of the $12,554.32 free cash split 12 ways | Q22: 5 | R22: ok | S22: 0.692 | T22: 65 | U22: 0.0284 | V22: -0.1395 | W22: 2 | X22: ok | Y22: 0.001 | Z22: ok | AA22: 100 | AC22: ok | AD22: up | AE22: 442.7164 | AF22: 409.2004 | AG22: 476.2324 | AH22: 46330 | AI22: 0.53 | AJ22: ok | AK22: 5 | AL22: BTIG Maintains Buy on Natera, Raises Price Target to $430 | AM22: 429.31 | AN22: 0.045 | AO22: 100357.58 | AP22: 12554.32 | AQ22: 0.0833 | AU22: paper | AV22: e246d111-60a8-4104-b741-c60e83ced992 | AW22: tdagent-buy-NTRA-1793200047226 | AX22: 46323.63 | AY22: 46323.63 | AZ22: 46323.63
A23: 22 | B23: 46323.672 | C23: 46323.464 | D23: 46323.63 | E23: BUY | F23: LNG | G23: Cheniere Energy Inc | H23: NYSE | I23: filled | J23: 3.489356 | K23: 299.7 | L23: =IF(AND(ISNUMBER(J23),ISNUMBER(K23)),J23*K23,"") | M23: 1045.77 | O23: 4+/5 green | P23: 5 of 5 green, time machine green, rank #3, 8.33% of the $12,554.32 free cash split 12 ways | Q23: 5 | R23: ok | S23: 0.66 | T23: 53 | U23: 0.0112 | V23: -0.1395 | W23: 3 | X23: ok | Y23: 0 | Z23: ok | AA23: 100 | AC23: ok | AD23: up | AE23: 304.4505 | AF23: 292.3993 | AG23: 316.5016 | AH23: 46330 | AI23: 0.54 | AJ23: ok | AK23: 0 | AM23: 299.63 | AN23: -0.0003 | AO23: 100357.58 | AP23: 12554.32 | AQ23: 0.0833 | AU23: paper | AV23: ad27f149-a613-4f91-8db8-e8d8a78946b6 | AW23: tdagent-buy-LNG-1793200047525 | AX23: 46323.63 | AY23: 46323.63 | AZ23: 46323.63
A24: 23 | B24: 46323.672 | C24: 46323.464 | D24: 46323.63 | E24: BUY | F24: MO | G24: Altria Group, Inc. | H24: NYSE | I24: filled | J24: 14.21449 | K24: 73.57 | L24: =IF(AND(ISNUMBER(J24),ISNUMBER(K24)),J24*K24,"") | M24: 1045.77 | O24: 4+/5 green | P24: 5 of 5 green, time machine green, rank #4, 8.33% of the $12,554.32 free cash split 12 ways | Q24: 5 | R24: ok | S24: 0.644 | T24: 45 | U24: 0.0097 | V24: -0.1395 | W24: 4 | X24: ok | Y24: 0.0002 | Z24: ok | AA24: 100 | AC24: ok | AD24: up | AE24: 74.5009 | AF24: 72.1861 | AG24: 76.8158 | AH24: 46330 | AI24: 0.55 | AJ24: ok | AK24: 0 | AM24: 73.56 | AN24: 0.0016 | AO24: 100357.58 | AP24: 12554.32 | AQ24: 0.0833 | AU24: paper | AV24: d54a6aee-45fb-4487-a477-f8cb923f7fd6 | AW24: tdagent-buy-MO-1793200047792 | AX24: 46323.63 | AY24: 46323.63 | AZ24: 46323.63
A25: 24 | B25: 46323.672 | C25: 46323.464 | D25: 46323.63 | E25: BUY | F25: KR | G25: The Kroger Co. | H25: NYSE | I25: filled | J25: 15.948757 | K25: 65.57 | L25: =IF(AND(ISNUMBER(J25),ISNUMBER(K25)),J25*K25,"") | M25: 1045.77 | O25: 4+/5 green | P25: 5 of 5 green, time machine green, rank #5, 8.33% of the $12,554.32 free cash split 12 ways | Q25: 5 | R25: ok | S25: 0.605 | T25: 38 | U25: 0.0136 | V25: -0.1395 | W25: 5 | X25: ok | Y25: 0.0002 | Z25: ok | AA25: 100 | AC25: ok | AD25: up | AE25: 66.6295 | AF25: 63.9933 | AG25: 69.2656 | AH25: 46330 | AI25: 0.56 | AJ25: ok | AK25: 3 | AL25: Evercore Maintains Buy Rating on The Kroger Co. | AM25: 65.56 | AN25: -0.0043 | AO25: 100357.58 | AP25: 12554.32 | AQ25: 0.0833 | AU25: paper | AV25: c3da3c32-f2c1-4d43-a318-6418c1dfd3c8 | AW25: tdagent-buy-KR-1793200048071 | AX25: 46323.63 | AY25: 46323.63 | AZ25: 46323.63
A26: 25 | B26: 46323.672 | C26: 46323.464 | D26: 46323.63 | E26: BUY | F26: WTW | G26: Willis Towers Watson Public Limited Company Ordinary Shares | H26: NASDAQ | I26: filled | J26: 3.2636145 | K26: 320.43 | L26: =IF(AND(ISNUMBER(J26),ISNUMBER(K26)),J26*K26,"") | M26: 1045.77 | O26: 4+/5 green | P26: 5 of 5 green, time machine green, rank #6, 8.33% of the $12,554.32 free cash split 12 ways | Q26: 5 | R26: ok | S26: 0.621 | T26: 29 | U26: 0.0212 | V26: -0.1395 | W26: 6 | X26: ok | Y26: 0.0006 | Z26: ok | AA26: 100 | AC26: ok | AD26: up | AE26: 324.7385 | AF26: 313.4173 | AG26: 336.0597 | AH26: 46330 | AI26: 0.53 | AJ26: ok | AK26: 0 | AM26: 320.21 | AN26: 0.0016 | AO26: 100357.58 | AP26: 12554.32 | AQ26: 0.0833 | AU26: paper | AV26: 5e449b92-c7e8-4ba7-84b2-04178ba9b5a4 | AW26: tdagent-buy-WTW-1793200048329 | AX26: 46323.63 | AY26: 46323.63 | AZ26: 46323.63
A27: 26 | B27: 46323.672 | C27: 46323.464 | D27: 46323.63 | E27: BUY | F27: ABBV | G27: ABBVIE INC. | H27: NYSE | I27: filled | J27: 3.6306069 | K27: 288.04 | L27: =IF(AND(ISNUMBER(J27),ISNUMBER(K27)),J27*K27,"") | M27: 1045.77 | O27: 4+/5 green | P27: 4 of 5 green, time machine green, rank #8, 8.33% of the $12,554.32 free cash split 12 ways | Q27: 4 | R27: ok | S27: 0.667 | T27: 39 | U27: 0.0177 | V27: -0.1395 | W27: 8 | X27: ok | Y27: 0.0006 | Z27: ok | AA27: 100 | AC27: ok | AD27: up | AE27: 291.4779 | AF27: 283.5332 | AG27: 299.4226 | AH27: 46330 | AI27: 0.57 | AJ27: watch | AK27: 6 | AL27: AbbVie Submits BLA for Etentamig to FDA for Multiple Myeloma | AM27: 288.3 | AN27: 0.0067 | AO27: 100357.58 | AP27: 12554.32 | AQ27: 0.0833 | AU27: paper | AV27: 8eb89be2-4ca4-45d4-910e-1f166d4d8478 | AW27: tdagent-buy-ABBV-1793200048709 | AX27: 46323.63 | AY27: 46323.63 | AZ27: 46323.63
A28: 27 | B28: 46323.672 | C28: 46323.464 | D28: 46323.63 | E28: BUY | F28: EQNR | G28: Equinor ASA American Depositary Shares (Each Representing One Ordinary Share, nominal value NOK 2.50 per share) | H28: NYSE | I28: filled | J28: 21.932886 | K28: 47.68 | L28: =IF(AND(ISNUMBER(J28),ISNUMBER(K28)),J28*K28,"") | M28: 1045.77 | O28: 4+/5 green | P28: 4 of 5 green, time machine green, rank #11, 8.33% of the $12,554.32 free cash split 12 ways | Q28: 4 | R28: ok | S28: 0.662 | T28: 77 | U28: 0.0135 | V28: -0.1395 | W28: 11 | X28: ok | Y28: 0.0004 | Z28: ok | AA28: 100 | AC28: ok | AD28: up | AE28: 48.5643 | AF28: 46.2786 | AG28: 50.85 | AH28: 46330 | AI28: 0.55 | AJ28: watch | AK28: 8 | AL28: Equinor Q3 2026 Earnings Call Transcript | AM28: 47.63 | AN28: 0.0129 | AO28: 100357.58 | AP28: 12554.32 | AQ28: 0.0833 | AU28: paper | AV28: b2ebe048-4e00-46e3-ad7e-fd294b463157 | AW28: tdagent-buy-EQNR-1793200049275 | AX28: 46323.63 | AY28: 46323.63 | AZ28: 46323.63
A29: 28 | B29: 46323.672 | C29: 46323.464 | D29: 46323.63 | E29: BUY | F29: ADP | G29: Automatic Data Processing, Inc. Common Stock | H29: NASDAQ | I29: filled | J29: 3.676299 | K29: 284.46 | L29: =IF(AND(ISNUMBER(J29),ISNUMBER(K29)),J29*K29,"") | M29: 1045.77 | O29: 4+/5 green | P29: 4 of 5 green, time machine green, rank #12, 8.33% of the $12,554.32 free cash split 12 ways | Q29: 4 | R29: ok | S29: 0.648 | T29: 54 | U29: 0.0132 | V29: -0.1395 | W29: 12 | X29: ok | Y29: 0.0018 | Z29: ok | AA29: 100 | AC29: ok | AD29: up | AE29: 288.7555 | AF29: 278.8917 | AG29: 298.6194 | AH29: 46330 | AI29: 0.56 | AJ29: watch | AK29: 9 | AL29: Automatic Data Processing Q1 2027 Earnings Call Transcript | AM29: 284.29 | AN29: -0.0278 | AO29: 100357.58 | AP29: 12554.32 | AQ29: 0.0833 | AU29: paper | AV29: ebfbb0f0-7770-43ff-9da5-d7832ec8fefe | AW29: tdagent-buy-ADP-1793200049536 | AX29: 46323.63 | AY29: 46323.63 | AZ29: 46323.63
A30: 29 | B30: 46323.672 | C30: 46323.464 | D30: 46323.63 | E30: BUY | F30: CTSH | G30: Cognizant Technology Solutions Corporation Class A Common Stock | H30: NASDAQ | I30: filled | J30: 15.713899 | K30: 66.55 | L30: =IF(AND(ISNUMBER(J30),ISNUMBER(K30)),J30*K30,"") | M30: 1045.77 | O30: 4+/5 green | P30: 4 of 5 green, time machine green, rank #13, 8.33% of the $12,554.32 free cash split 12 ways | Q30: 4 | R30: ok | S30: 0.587 | T30: 46 | U30: 0.0115 | V30: -0.1395 | W30: 13 | X30: ok | Y30: 0.0003 | Z30: ok | AA30: 100 | AC30: ok | AD30: up | AE30: 68.1648 | AF30: 64.2528 | AG30: 72.0767 | AH30: 46330 | AI30: 0.55 | AJ30: watch | AK30: 10 | AL30: Morgan Stanley Downgrades Cognizant Technology Solutions to Neutral | AM30: 66.58 | AN30: 0.0059 | AO30: 100357.58 | AP30: 12554.32 | AQ30: 0.0833 | AU30: paper | AV30: 96d36240-c72a-4a79-8467-1c5b3b8d6462 | AW30: tdagent-buy-CTSH-1793200049798 | AX30: 46323.63 | AY30: 46323.63 | AZ30: 46323.63
A31: 30 | B31: 46323.672 | C31: 46323.464 | D31: 46323.63 | E31: BUY | F31: MA | G31: Mastercard Incorporated | H31: NYSE | I31: filled | J31: 1.7040581 | K31: 613.688 | L31: =IF(AND(ISNUMBER(J31),ISNUMBER(K31)),J31*K31,"") | M31: 1045.77 | O31: 4+/5 green | P31: 4 of 5 green, time machine green, rank #14, 8.33% of the $12,554.32 free cash split 12 ways | Q31: 4 | R31: ok | S31: 0.553 | T31: 47 | U31: 0.0065 | V31: -0.1395 | W31: 14 | X31: ok | Y31: 0.0006 | Z31: ok | AA31: 100 | AC31: ok | AD31: up | AE31: 620.3299 | AF31: 604.5177 | AG31: 636.1421 | AH31: 46330 | AI31: 0.57 | AJ31: watch | AK31: 8 | AL31: Visa Earnings Prediction Market Preview: What Will Ryan McInerney Say? | AM31: 613.705 | AN31: 0.0068 | AO31: 100357.58 | AP31: 12554.32 | AQ31: 0.0833 | AU31: paper | AV31: 394e3ad3-8d54-4448-ba7c-fce04cf9d2f4 | AW31: tdagent-buy-MA-1793200050051 | AX31: 46323.63 | AY31: 46323.63 | AZ31: 46323.63
A32: 31 | B32: 46323.672 | C32: 46323.464 | D32: 46323.63 | E32: BUY | F32: CNC | G32: Centene Corporation | H32: NYSE | I32: filled | J32: 15.180142 | K32: 68.89 | L32: =IF(AND(ISNUMBER(J32),ISNUMBER(K32)),J32*K32,"") | M32: 1045.77 | O32: 4+/5 green | P32: 4 of 5 green, time machine green, rank #15, 8.33% of the $12,554.32 free cash split 12 ways | Q32: 4 | R32: ok | S32: 0.568 | T32: 44 | U32: 0.0126 | V32: -0.1395 | W32: 15 | X32: ok | Y32: 0.0007 | Z32: ok | AA32: 100 | AC32: ok | AD32: up | AE32: 70.1768 | AF32: 66.9598 | AG32: 73.3939 | AH32: 46330 | AI32: 0.53 | AJ32: watch | AK32: 10 | AL32: Cantor Fitzgerald Upgrades Centene to Overweight and Raises Price Target to $79 | AM32: 68.94 | AN32: 0.0013 | AO32: 100357.58 | AP32: 12554.32 | AQ32: 0.0833 | AU32: paper | AV32: 545413f4-a3a5-4501-a6a3-27a435a4337f | AW32: tdagent-buy-CNC-1793200050304 | AX32: 46323.63 | AY32: 46323.63 | AZ32: 46323.63
A33: 32 | B33: 46323.673 | C33: 46323.465 | D33: 46323.632 | E33: SELL | F33: ADP | G33: ADP | H33: NASDAQ | I33: filled | J33: 3.676299 | K33: 283.51 | L33: =IF(AND(ISNUMBER(J33),ISNUMBER(K33)),J33*K33,"") | N33: 3.676299 | O33: bad day | P33: Bad day: down 3.1% today and only 4 of 5 green | Q33: 4 | R33: ok | S33: 0.648 | T33: 54 | U33: 0.0132 | V33: -0.1395 | X33: ok | Y33: 0.0001 | Z33: ok | AA33: 100 | AC33: ok | AD33: up | AE33: 288.361 | AF33: 278.4835 | AG33: 298.2385 | AH33: 46330 | AI33: 0.56 | AJ33: watch | AK33: 9 | AL33: Automatic Data Processing Q1 2027 Earnings Call Transcript | AM33: 284.44 | AN33: -0.0291 | AO33: 100436.88 | AP33: 5.2 | AQ33: 0.0833 | AR33: 3.676299 | AS33: 284.46 | AT33: -0.0017 | AU33: paper | AV33: 91487c54-b2fb-4b1a-a476-77ac1f697fc3 | AW33: tdagent-sell-ADP-1793200180561 | AX33: 46323.632 | AY33: 46323.632 | AZ33: 46323.632
A34: 33 | B34: 46323.678 | C34: 46323.469 | D34: 46323.636 | E34: SELL | F34: MA | G34: MA | H34: NYSE | I34: filled | J34: 0.85202904 | K34: 614.554 | L34: =IF(AND(ISNUMBER(J34),ISNUMBER(K34)),J34*K34,"") | N34: 0.85202904 | O34: 3 green: sell half | P34: 3 of 5 green: start selling (half) | Q34: 3 | R34: ok | S34: 0.553 | T34: 47 | U34: 0.0065 | V34: -0.1395 | X34: ok | Y34: 0.0001 | Z34: ok | AA34: 100 | AC34: watch | AD34: flat | AE34: 614.625 | AF34: 598.7848 | AG34: 630.4652 | AH34: 46330 | AI34: 0.5 | AJ34: watch | AK34: 8 | AL34: Visa Earnings Prediction Market Preview: What Will Ryan McInerney Say? | AM34: 614.625 | AN34: 0.0078 | AO34: 100369.37 | AP34: 1047.47 | AQ34: 0.0833 | AR34: 1.7040581 | AS34: 613.688 | AT34: 0.0019 | AU34: paper | AV34: 2a80a5f5-7036-429a-a454-9494a1feec10 | AW34: tdagent-sell-MA-1793200550863 | AX34: 46323.636 | AY34: 46323.636 | AZ34: 46323.636
A35: 34 | B35: 46323.678 | C35: 46323.469 | D35: 46323.636 | E35: BUY | F35: MPC | G35: MARATHON PETROLEUM CORPORATION | H35: NYSE | I35: filled | J35: 0.19946772 | K35: 437.364 | L35: =IF(AND(ISNUMBER(J35),ISNUMBER(K35)),J35*K35,"") | M35: 87.25 | O35: 4+/5 green | P35: 4 of 5 green, time machine green, rank #5, 8.33% of the $1,047.47 free cash split 12 ways | Q35: 4 | R35: ok | S35: 0.674 | T35: 86 | U35: 0.0246 | V35: -0.1395 | W35: 5 | X35: ok | Y35: 0.0011 | Z35: ok | AA35: 80 | AB35: One day (-7.4%) did 74% of the 10-day move. The trend rests on a single jump. | AC35: ok | AD35: up | AE35: 446.2446 | AF35: 422.0831 | AG35: 470.4061 | AH35: 46330 | AI35: 0.54 | AJ35: watch | AK35: 4 | AL35: Refiner Stocks Suffer Worst Day Since the Tariff Shock: The Threat Is Not Cheaper Oil | AM35: 436.58 | AN35: 0.0015 | AO35: 100369.37 | AP35: 1047.47 | AQ35: 0.0833 | AU35: paper | AV35: 795c1192-92f0-4087-a19e-e4a4afbb099c | AW35: tdagent-buy-MPC-1793200551740 | AX35: 46323.636 | AY35: 46323.636 | AZ35: 46323.636
A36: 35 | B36: 46323.678 | C36: 46323.469 | D36: 46323.636 | E36: BUY | F36: EQT | G36: EQT CORP | H36: NYSE | I36: filled | J36: 1.562265 | K36: 55.842 | L36: =IF(AND(ISNUMBER(J36),ISNUMBER(K36)),J36*K36,"") | M36: 87.25 | O36: 4+/5 green | P36: 4 of 5 green, time machine green, rank #6, 8.33% of the $1,047.47 free cash split 12 ways | Q36: 4 | R36: ok | S36: 0.552 | T36: 29 | U36: 0.0017 | V36: -0.1395 | W36: 6 | X36: ok | Y36: 0.0004 | Z36: ok | AA36: 90 | AB36: Price gapped 5.1% at an open in the last week. | AC36: ok | AD36: up | AE36: 56.5868 | AF36: 54.5198 | AG36: 58.6539 | AH36: 46330 | AI36: 0.54 | AJ36: watch | AK36: 10 | AL36: UBS Maintains Buy on EQT, Lowers Price Target to $75 | AM36: 55.78 | AN36: -0.0094 | AO36: 100369.37 | AP36: 1047.47 | AQ36: 0.0833 | AU36: paper | AV36: 8dda163c-11b6-4647-b796-a4421efe2a2c | AW36: tdagent-buy-EQT-1793200552082 | AX36: 46323.636 | AY36: 46323.636 | AZ36: 46323.636
A37: 36 | B37: 46323.678 | C37: 46323.469 | D37: 46323.636 | E37: BUY | F37: PSX | G37: PHILLIPS 66 | H37: NYSE | I37: filled | J37: 0.32315899 | K37: 269.96 | L37: =IF(AND(ISNUMBER(J37),ISNUMBER(K37)),J37*K37,"") | M37: 87.25 | O37: 4+/5 green | P37: 4 of 5 green, time machine green, rank #7, 8.33% of the $1,047.47 free cash split 12 ways | Q37: 4 | R37: ok | S37: 0.569 | T37: 72 | U37: 0.015 | V37: -0.1395 | W37: 7 | X37: ok | Y37: 0.0016 | Z37: ok | AA37: 80 | AB37: One day (-7.0%) did 75% of the 10-day move. The trend rests on a single jump. | AC37: ok | AD37: up | AE37: 274.4826 | AF37: 261.9386 | AG37: 287.0267 | AH37: 46330 | AI37: 0.53 | AJ37: watch | AK37: 9 | AL37: Refiner Stocks Suffer Worst Day Since the Tariff Shock: The Threat Is Not Cheaper Oil | AM37: 269.89 | AN37: 0.004 | AO37: 100369.37 | AP37: 1047.47 | AQ37: 0.0833 | AU37: paper | AV37: 13fe6aef-0823-407e-9dae-d781ac0376cd | AW37: tdagent-buy-PSX-1793200552421 | AX37: 46323.636 | AY37: 46323.636 | AZ37: 46323.636
A38: 37 | B38: 46323.689 | C38: 46323.481 | D38: 46323.648 | E38: SELL | F38: CNC | G38: CNC | H38: NYSE | I38: filled | J38: 7.5900711 | K38: 69.01 | L38: =IF(AND(ISNUMBER(J38),ISNUMBER(K38)),J38*K38,"") | N38: 7.5900711 | O38: 3 green: sell half | P38: 3 of 5 green: start selling (half) | Q38: 3 | R38: ok | S38: 0.568 | T38: 44 | U38: 0.0126 | V38: -0.1395 | X38: watch | Y38: 0.0096 | Z38: ok | AA38: 100 | AC38: ok | AD38: up | AE38: 70.3807 | AF38: 67.1539 | AG38: 73.6076 | AH38: 46330 | AI38: 0.53 | AJ38: watch | AK38: 10 | AL38: Cantor Fitzgerald Upgrades Centene to Overweight and Raises Price Target to $79 | AM38: 69.09 | AN38: 0.0042 | AO38: 100387.39 | AP38: 1309.37 | AQ38: 0.0833 | AR38: 15.180142 | AS38: 68.89 | AT38: 0.0021 | AU38: paper | AV38: 3b93b9ef-5e93-4cd1-a10b-1cea19899888 | AW38: tdagent-sell-CNC-1793201560611 | AX38: 46323.648 | AY38: 46323.648 | AZ38: 46323.647
A39: 38 | B39: 46323.689 | C39: 46323.481 | D39: 46323.648 | E39: BUY | F39: DINO | G39: HF Sinclair Corporation | H39: NYSE | I39: filled | J39: 0.97394131 | K39: 111.978 | L39: =IF(AND(ISNUMBER(J39),ISNUMBER(K39)),J39*K39,"") | M39: 109.07 | O39: 4+/5 green | P39: 4 of 5 green, time machine green, rank #5, 8.33% of the $1,309.37 free cash split 12 ways | Q39: 4 | R39: ok | S39: 0.6 | T39: 70 | U39: 0.0194 | V39: -0.1395 | W39: 5 | X39: ok | Y39: 0.0028 | Z39: ok | AA39: 80 | AB39: One day (-8.9%) did 73% of the 10-day move. The trend rests on a single jump. | AC39: ok | AD39: up | AE39: 114.8338 | AF39: 108.2243 | AG39: 121.4432 | AH39: 46330 | AI39: 0.53 | AJ39: watch | AK39: 10 | AL39: HF Sinclair Q3 2026 Earnings Call Transcript | AM39: 112.31 | AN39: -0.0169 | AO39: 100387.39 | AP39: 1309.37 | AQ39: 0.0833 | AU39: paper | AV39: f522894d-4a29-4dac-9deb-1e6b36780c89 | AW39: tdagent-buy-DINO-1793201561401 | AX39: 46323.648 | AY39: 46323.648 | AZ39: 46323.647
A40: 39 | B40: 46323.693 | C40: 46323.485 | D40: 46323.652 | E40: SELL | F40: DINO | G40: DINO | H40: NYSE | I40: filled | J40: 0.48697065 | K40: 111.736 | L40: =IF(AND(ISNUMBER(J40),ISNUMBER(K40)),J40*K40,"") | N40: 0.48697065 | O40: 3 green: sell half | P40: 3 of 5 green: start selling (half) | Q40: 3 | R40: ok | S40: 0.6 | T40: 70 | U40: 0.0194 | V40: -0.1395 | X40: ok | Y40: 0.0004 | Z40: ok | AA40: 80 | AB40: One day (-8.9%) did 72% of the 10-day move. The trend rests on a single jump. | AC40: watch | AD40: flat | AE40: 111.92 | AF40: 105.318 | AG40: 118.522 | AH40: 46330 | AI40: 0.5 | AJ40: watch | AK40: 10 | AL40: HF Sinclair Q3 2026 Earnings Call Transcript | AM40: 111.92 | AN40: -0.0193 | AO40: 100311.45 | AP40: 1724.1 | AQ40: 0.0833 | AR40: 0.97394131 | AS40: 111.978 | AT40: -0.0015 | AU40: paper | AV40: b7e8fde4-772d-45c4-baa3-f36239fb4db9 | AW40: tdagent-sell-DINO-1793201915224 | AX40: 46323.652 | AY40: 46323.652 | AZ40: 46323.652
...

Sheet Round trips
A1: Symbol | B1: Company | C1: Bought (Berlin) | D1: Bought (New York) | E1: Buy price $ | F1: Qty | G1: Cost $ | H1: Sold (Berlin) | I1: Sold (New York) | J1: Sell price $ | K1: Proceeds $ | L1: P/L $ | M1: P/L % | N1: Days held | O1: Exit rule | P1: Status
A2: TMO | B2: Thermo Fisher Scientific, Inc. | C2: 46322.716 | D2: 46322.508 | E2: 694.93 | F2: 11.986804 | G2: =E2*F2 | H2: 46322.868 | I2: 46322.66 | J2: 699.16667 | K2: =IF(ISNUMBER(J2),J2*F2,"") | L2: =IF(ISNUMBER(J2),K2-G2,"") | M2: =IF(ISNUMBER(J2),L2/G2,"") | N2: =IF(ISNUMBER(H2),H2-C2,"") | O2: evening under 5% | P2: Closed
A3: SHEL | B3: Shell plc American Depositary Shares (Each represents two Ordinary shares) | C3: 46322.796 | D3: 46322.587 | E3: 104.93 | F3: 79.416754 | G3: =E3*F3 | H3: 46322.868 | I3: 46322.659 | J3: 104.96 | K3: =IF(ISNUMBER(J3),J3*F3,"") | L3: =IF(ISNUMBER(J3),K3-G3,"") | M3: =IF(ISNUMBER(J3),L3/G3,"") | N3: =IF(ISNUMBER(H3),H3-C3,"") | O3: evening under 5% | P3: Closed
A4: SHEL | B4: Shell plc American Depositary Shares (Each represents two Ordinary shares) | C4: 46323.606 | D4: 46323.398 | E4: 105 | F4: 79.375048 | G4: =E4*F4 | K4: =IF(ISNUMBER(J4),J4*F4,"") | L4: =IF(ISNUMBER(J4),K4-G4,"") | M4: =IF(ISNUMBER(J4),L4/G4,"") | N4: =IF(ISNUMBER(H4),H4-C4,"") | P4: Open
A5: UTHR | B5: United Therapeutics Corporation Common Stock | C5: 46323.606 | D5: 46323.398 | E5: 585.96 | F5: 7.1117312 | G5: =E5*F5 | H5: 46323.661 | I5: 46323.453 | J5: 588.24 | K5: =IF(ISNUMBER(J5),J5*F5,"") | L5: =IF(ISNUMBER(J5),K5-G5,"") | M5: =IF(ISNUMBER(J5),L5/G5,"") | N5: =IF(ISNUMBER(H5),H5-C5,"") | O5: 3 green: sell half | P5: Closed
A6: UTHR | B6: United Therapeutics Corporation Common Stock | C6: 46323.606 | D6: 46323.398 | E6: 585.96 | F6: 7.1117312 | G6: =E6*F6 | K6: =IF(ISNUMBER(J6),J6*F6,"") | L6: =IF(ISNUMBER(J6),K6-G6,"") | M6: =IF(ISNUMBER(J6),L6/G6,"") | N6: =IF(ISNUMBER(H6),H6-C6,"") | P6: Open
A7: ILMN | B7: Illumina, Inc. Common Stock | C7: 46323.606 | D7: 46323.398 | E7: 281 | F7: 29.659715 | G7: =E7*F7 | K7: =IF(ISNUMBER(J7),J7*F7,"") | L7: =IF(ISNUMBER(J7),K7-G7,"") | M7: =IF(ISNUMBER(J7),L7/G7,"") | N7: =IF(ISNUMBER(H7),H7-C7,"") | P7: Open
A8: EBAY | B8: eBay Inc. Common Stock | C8: 46323.606 | D8: 46323.398 | E8: 118.83732 | F8: 70.132683 | G8: =E8*F8 | K8: =IF(ISNUMBER(J8),J8*F8,"") | L8: =IF(ISNUMBER(J8),K8-G8,"") | M8: =IF(ISNUMBER(J8),L8/G8,"") | N8: =IF(ISNUMBER(H8),H8-C8,"") | P8: Open
A9: DT | B9: Dynatrace, Inc. | C9: 46323.607 | D9: 46323.398 | E9: 63.965309 | F9: 130.29531 | G9: =E9*F9 | K9: =IF(ISNUMBER(J9),J9*F9,"") | L9: =IF(ISNUMBER(J9),K9-G9,"") | M9: =IF(ISNUMBER(J9),L9/G9,"") | N9: =IF(ISNUMBER(H9),H9-C9,"") | P9: Open
A10: MCK | B10: McKesson Corporation | C10: 46323.607 | D10: 46323.398 | E10: 966.85025 | F10: 8.6201353 | G10: =E10*F10 | K10: =IF(ISNUMBER(J10),J10*F10,"") | L10: =IF(ISNUMBER(J10),K10-G10,"") | M10: =IF(ISNUMBER(J10),L10/G10,"") | N10: =IF(ISNUMBER(H10),H10-C10,"") | P10: Open
A11: TMO | B11: Thermo Fisher Scientific, Inc. | C11: 46323.607 | D11: 46323.398 | E11: 698.19344 | F11: 11.937064 | G11: =E11*F11 | K11: =IF(ISNUMBER(J11),J11*F11,"") | L11: =IF(ISNUMBER(J11),K11-G11,"") | M11: =IF(ISNUMBER(J11),L11/G11,"") | N11: =IF(ISNUMBER(H11),H11-C11,"") | P11: Open
A12: CBOE | B12: Cboe Global Markets, Inc. | C12: 46323.607 | D12: 46323.399 | E12: 322.60387 | F12: 25.834718 | G12: =E12*F12 | K12: =IF(ISNUMBER(J12),J12*F12,"") | L12: =IF(ISNUMBER(J12),K12-G12,"") | M12: =IF(ISNUMBER(J12),L12/G12,"") | N12: =IF(ISNUMBER(H12),H12-C12,"") | P12: Open
A13: OXY | B13: Occidental Petroleum Corporation | C13: 46323.607 | D13: 46323.399 | E13: 62.998354 | F13: 132.2952 | G13: =E13*F13 | K13: =IF(ISNUMBER(J13),J13*F13,"") | L13: =IF(ISNUMBER(J13),K13-G13,"") | M13: =IF(ISNUMBER(J13),L13/G13,"") | N13: =IF(ISNUMBER(H13),H13-C13,"") | P13: Open
A14: IQV | B14: IQVIA Holdings Inc. | C14: 46323.607 | D14: 46323.399 | E14: 274.52062 | F14: 15.17988 | G14: =E14*F14 | H14: 46323.609 | I14: 46323.401 | J14: 273.44 | K14: =IF(ISNUMBER(J14),J14*F14,"") | L14: =IF(ISNUMBER(J14),K14-G14,"") | M14: =IF(ISNUMBER(J14),L14/G14,"") | N14: =IF(ISNUMBER(H14),H14-C14,"") | O14: 3 green: sell half | P14: Closed
A15: IQV | B15: IQVIA Holdings Inc. | C15: 46323.607 | D15: 46323.399 | E15: 274.52062 | F15: 15.17988 | G15: =E15*F15 | K15: =IF(ISNUMBER(J15),J15*F15,"") | L15: =IF(ISNUMBER(J15),K15-G15,"") | M15: =IF(ISNUMBER(J15),L15/G15,"") | N15: =IF(ISNUMBER(H15),H15-C15,"") | P15: Open
A16: MNST | B16: Monster Beverage Corporation | C16: 46323.607 | D16: 46323.399 | E16: 45.162906 | F16: 184.54039 | G16: =E16*F16 | K16: =IF(ISNUMBER(J16),J16*F16,"") | L16: =IF(ISNUMBER(J16),K16-G16,"") | M16: =IF(ISNUMBER(J16),L16/G16,"") | N16: =IF(ISNUMBER(H16),H16-C16,"") | P16: Open
A17: PBR.A | B17: Petroleo Brasileiro S.A.-Petrobras | C17: 46323.607 | D17: 46323.399 | E17: 19.69562 | F17: 211.57953 | G17: =E17*F17 | H17: 46323.609 | I17: 46323.401 | J17: 19.755625 | K17: =IF(ISNUMBER(J17),J17*F17,"") | L17: =IF(ISNUMBER(J17),K17-G17,"") | M17: =IF(ISNUMBER(J17),L17/G17,"") | N17: =IF(ISNUMBER(H17),H17-C17,"") | O17: 3 green: sell half | P17: Closed
A18: PBR.A | B18: Petroleo Brasileiro S.A.-Petrobras | C18: 46323.607 | D18: 46323.399 | E18: 19.69562 | F18: 211.57953 | G18: =E18*F18 | K18: =IF(ISNUMBER(J18),J18*F18,"") | L18: =IF(ISNUMBER(J18),K18-G18,"") | M18: =IF(ISNUMBER(J18),L18/G18,"") | N18: =IF(ISNUMBER(H18),H18-C18,"") | P18: Open
A19: LNG | B19: Cheniere Energy Inc | C19: 46323.672 | D19: 46323.464 | E19: 299.7 | F19: 3.489356 | G19: =E19*F19 | K19: =IF(ISNUMBER(J19),J19*F19,"") | L19: =IF(ISNUMBER(J19),K19-G19,"") | M19: =IF(ISNUMBER(J19),L19/G19,"") | N19: =IF(ISNUMBER(H19),H19-C19,"") | P19: Open
A20: ADI | B20: Analog Devices, Inc. Common Stock | C20: 46323.672 | D20: 46323.464 | E20: 425 | F20: 2.4606118 | G20: =E20*F20 | K20: =IF(ISNUMBER(J20),J20*F20,"") | L20: =IF(ISNUMBER(J20),K20-G20,"") | M20: =IF(ISNUMBER(J20),L20/G20,"") | N20: =IF(ISNUMBER(H20),H20-C20,"") | P20: Open
A21: NTRA | B21: Natera, Inc. Common Stock | C21: 46323.672 | D21: 46323.464 | E21: 429.56 | F21: 2.4344911 | G21: =E21*F21 | K21: =IF(ISNUMBER(J21),J21*F21,"") | L21: =IF(ISNUMBER(J21),K21-G21,"") | M21: =IF(ISNUMBER(J21),L21/G21,"") | N21: =IF(ISNUMBER(H21),H21-C21,"") | P21: Open
A22: MO | B22: Altria Group, Inc. | C22: 46323.672 | D22: 46323.464 | E22: 73.57 | F22: 14.21449 | G22: =E22*F22 | K22: =IF(ISNUMBER(J22),J22*F22,"") | L22: =IF(ISNUMBER(J22),K22-G22,"") | M22: =IF(ISNUMBER(J22),L22/G22,"") | N22: =IF(ISNUMBER(H22),H22-C22,"") | P22: Open
A23: WTW | B23: Willis Towers Watson Public Limited Company Ordinary Shares | C23: 46323.672 | D23: 46323.464 | E23: 320.43 | F23: 3.2636145 | G23: =E23*F23 | K23: =IF(ISNUMBER(J23),J23*F23,"") | L23: =IF(ISNUMBER(J23),K23-G23,"") | M23: =IF(ISNUMBER(J23),L23/G23,"") | N23: =IF(ISNUMBER(H23),H23-C23,"") | P23: Open
A24: KR | B24: The Kroger Co. | C24: 46323.672 | D24: 46323.464 | E24: 65.57 | F24: 15.948757 | G24: =E24*F24 | K24: =IF(ISNUMBER(J24),J24*F24,"") | L24: =IF(ISNUMBER(J24),K24-G24,"") | M24: =IF(ISNUMBER(J24),L24/G24,"") | N24: =IF(ISNUMBER(H24),H24-C24,"") | P24: Open
A25: ABBV | B25: ABBVIE INC. | C25: 46323.672 | D25: 46323.464 | E25: 288.04 | F25: 3.6306069 | G25: =E25*F25 | K25: =IF(ISNUMBER(J25),J25*F25,"") | L25: =IF(ISNUMBER(J25),K25-G25,"") | M25: =IF(ISNUMBER(J25),L25/G25,"") | N25: =IF(ISNUMBER(H25),H25-C25,"") | P25: Open
A26: MA | B26: Mastercard Incorporated | C26: 46323.672 | D26: 46323.464 | E26: 613.688 | F26: 0.85202904 | G26: =E26*F26 | H26: 46323.678 | I26: 46323.469 | J26: 614.554 | K26: =IF(ISNUMBER(J26),J26*F26,"") | L26: =IF(ISNUMBER(J26),K26-G26,"") | M26: =IF(ISNUMBER(J26),L26/G26,"") | N26: =IF(ISNUMBER(H26),H26-C26,"") | O26: 3 green: sell half | P26: Closed
A27: MA | B27: Mastercard Incorporated | C27: 46323.672 | D27: 46323.464 | E27: 613.688 | F27: 0.85202904 | G27: =E27*F27 | K27: =IF(ISNUMBER(J27),J27*F27,"") | L27: =IF(ISNUMBER(J27),K27-G27,"") | M27: =IF(ISNUMBER(J27),L27/G27,"") | N27: =IF(ISNUMBER(H27),H27-C27,"") | P27: Open
A28: ADP | B28: Automatic Data Processing, Inc. Common Stock | C28: 46323.672 | D28: 46323.464 | E28: 284.46 | F28: 3.676299 | G28: =E28*F28 | H28: 46323.673 | I28: 46323.465 | J28: 283.51 | K28: =IF(ISNUMBER(J28),J28*F28,"") | L28: =IF(ISNUMBER(J28),K28-G28,"") | M28: =IF(ISNUMBER(J28),L28/G28,"") | N28: =IF(ISNUMBER(H28),H28-C28,"") | O28: bad day | P28: Closed
A29: CNC | B29: Centene Corporation | C29: 46323.672 | D29: 46323.464 | E29: 68.89 | F29: 7.5900711 | G29: =E29*F29 | H29: 46323.689 | I29: 46323.481 | J29: 69.01 | K29: =IF(ISNUMBER(J29),J29*F29,"") | L29: =IF(ISNUMBER(J29),K29-G29,"") | M29: =IF(ISNUMBER(J29),L29/G29,"") | N29: =IF(ISNUMBER(H29),H29-C29,"") | O29: 3 green: sell half | P29: Closed
A30: CNC | B30: Centene Corporation | C30: 46323.672 | D30: 46323.464 | E30: 68.89 | F30: 7.5900711 | G30: =E30*F30 | K30: =IF(ISNUMBER(J30),J30*F30,"") | L30: =IF(ISNUMBER(J30),K30-G30,"") | M30: =IF(ISNUMBER(J30),L30/G30,"") | N30: =IF(ISNUMBER(H30),H30-C30,"") | P30: Open
A31: CTSH | B31: Cognizant Technology Solutions Corporation Class A Common Stock | C31: 46323.672 | D31: 46323.464 | E31: 66.55 | F31: 15.713899 | G31: =E31*F31 | K31: =IF(ISNUMBER(J31),J31*F31,"") | L31: =IF(ISNUMBER(J31),K31-G31,"") | M31: =IF(ISNUMBER(J31),L31/G31,"") | N31: =IF(ISNUMBER(H31),H31-C31,"") | P31: Open
A32: EQNR | B32: Equinor ASA American Depositary Shares (Each Representing One Ordinary Share, nominal value NOK 2.50 per share) | C32: 46323.672 | D32: 46323.464 | E32: 47.68 | F32: 21.932886 | G32: =E32*F32 | K32: =IF(ISNUMBER(J32),J32*F32,"") | L32: =IF(ISNUMBER(J32),K32-G32,"") | M32: =IF(ISNUMBER(J32),L32/G32,"") | N32: =IF(ISNUMBER(H32),H32-C32,"") | P32: Open
A33: MPC | B33: MARATHON PETROLEUM CORPORATION | C33: 46323.678 | D33: 46323.469 | E33: 437.364 | F33: 0.19946772 | G33: =E33*F33 | K33: =IF(ISNUMBER(J33),J33*F33,"") | L33: =IF(ISNUMBER(J33),K33-G33,"") | M33: =IF(ISNUMBER(J33),L33/G33,"") | N33: =IF(ISNUMBER(H33),H33-C33,"") | P33: Open
A34: EQT | B34: EQT CORP | C34: 46323.678 | D34: 46323.469 | E34: 55.842 | F34: 1.562265 | G34: =E34*F34 | K34: =IF(ISNUMBER(J34),J34*F34,"") | L34: =IF(ISNUMBER(J34),K34-G34,"") | M34: =IF(ISNUMBER(J34),L34/G34,"") | N34: =IF(ISNUMBER(H34),H34-C34,"") | P34: Open
A35: PSX | B35: PHILLIPS 66 | C35: 46323.678 | D35: 46323.469 | E35: 269.96 | F35: 0.32315899 | G35: =E35*F35 | K35: =IF(ISNUMBER(J35),J35*F35,"") | L35: =IF(ISNUMBER(J35),K35-G35,"") | M35: =IF(ISNUMBER(J35),L35/G35,"") | N35: =IF(ISNUMBER(H35),H35-C35,"") | P35: Open
A36: DINO | B36: HF Sinclair Corporation | C36: 46323.689 | D36: 46323.481 | E36: 111.978 | F36: 0.48697065 | G36: =E36*F36 | H36: 46323.693 | I36: 46323.485 | J36: 111.736 | K36: =IF(ISNUMBER(J36),J36*F36,"") | L36: =IF(ISNUMBER(J36),K36-G36,"") | M36: =IF(ISNUMBER(J36),L36/G36,"") | N36: =IF(ISNUMBER(H36),H36-C36,"") | O36: 3 green: sell half | P36: Closed
A37: DINO | B37: HF Sinclair Corporation | C37: 46323.689 | D37: 46323.481 | E37: 111.978 | F37: 0.48697065 | G37: =E37*F37 | K37: =IF(ISNUMBER(J37),J37*F37,"") | L37: =IF(ISNUMBER(J37),K37-G37,"") | M37: =IF(ISNUMBER(J37),L37/G37,"") | N37: =IF(ISNUMBER(H37),H37-C37,"") | P37: Open
A38: LLY | B38: Eli Lilly & Co. | C38: 46323.71 | D38: 46323.501 | E38: 1291.586 | F38: 0.11468845 | G38: =E38*F38 | K38: =IF(ISNUMBER(J38),J38*F38,"") | L38: =IF(ISNUMBER(J38),K38-G38,"") | M38: =IF(ISNUMBER(J38),L38/G38,"") | N38: =IF(ISNUMBER(H38),H38-C38,"") | P38: Open
A39: REGN | B39: Regeneron Pharmaceuticals, Inc. Common Stock | C39: 46323.723 | D39: 46323.515 | E39: 811.418 | F39: 0.16736133 | G39: =E39*F39 | K39: =IF(ISNUMBER(J39),J39*F39,"") | L39: =IF(ISNUMBER(J39),K39-G39,"") | M39: =IF(ISNUMBER(J39),L39/G39,"") | N39: =IF(ISNUMBER(H39),H39-C39,"") | P39: Open

Sheet Rules
A1: Rule | B1: What it does
A2: Master switch | B2: Weekly time machine replays the last 6 months with these rules; if it would have lost money, no new buys
A3: Buy | B3: 4 or 5 of 5 green, time machine and data-is-real green (vetoes), nothing red, not already held; funds/ETFs skipped
A4: Cash only | B4: Never uses margin
A5: No buys before close | B5: Last 30 minutes of the session: sells only
A6: Daily loss guard | B6: No new buys on a day the account is down 5% or more
A7: Exit: 3 of 5 green | B7: Sell half, once (not again within 3 days)
A8: Exit: 2 or fewer of 5, or time machine red | B8: Sell everything
A9: Sell line | B9: 5% below the highest price since buying, never lower than 5% under the buy price (bought 100, high 200: sells at 190). Also kept as a real Alpaca stop order that moves up with the price
A10: Evening | B10: In the last 30 minutes before the close, everything up less than +5% is sold; +5% or more stays overnight. No buys in the last 30 minutes
A11: Buy loop | B11: Each buy uses 8.33% of the cash available at that moment, repeated for every buy-ready stock (up to 100 stocks, orders of at least $5); never buys back a stock sold the same day
A12: Bad day | B12: Down 3% today and not 5 of 5 green: sell everything
... A19: Check 5 · Time machine | B19: Replays the stock's past year: on days it looked green, did it rise over the next 5 trading days? Green at 55%+ hit rate and positive average
